[2024-06-26T13:04:43.788+0000] {local_task_job_runner.py:120} INFO - ::group::Pre task execution logs
[2024-06-26T13:04:43.813+0000] {taskinstance.py:2076} INFO - Dependencies all met for dep_context=non-requeueable deps ti=<TaskInstance: etl_dag.load_to_gcs scheduled__2024-06-25T00:00:00+00:00 [queued]>
[2024-06-26T13:04:43.974+0000] {taskinstance.py:2076} INFO - Dependencies all met for dep_context=requeueable deps ti=<TaskInstance: etl_dag.load_to_gcs scheduled__2024-06-25T00:00:00+00:00 [queued]>
[2024-06-26T13:04:43.975+0000] {taskinstance.py:2306} INFO - Starting attempt 2 of 2
[2024-06-26T13:04:43.990+0000] {taskinstance.py:2330} INFO - Executing <Task(PostgresToGCSOperator): load_to_gcs> on 2024-06-25 00:00:00+00:00
[2024-06-26T13:04:43.997+0000] {warnings.py:112} WARNING - /home/***/.local/lib/python3.12/site-packages/***/task/task_runner/standard_task_runner.py:61: DeprecationWarning: This process (pid=153) is multi-threaded, use of fork() may lead to deadlocks in the child.
  pid = os.fork()

[2024-06-26T13:04:43.998+0000] {standard_task_runner.py:63} INFO - Started process 155 to run task
[2024-06-26T13:04:43.998+0000] {standard_task_runner.py:90} INFO - Running: ['***', 'tasks', 'run', 'etl_dag', 'load_to_gcs', 'scheduled__2024-06-25T00:00:00+00:00', '--job-id', '6', '--raw', '--subdir', 'DAGS_FOLDER/dag_etl.py', '--cfg-path', '/tmp/tmp0vbnpzwt']
[2024-06-26T13:04:43.999+0000] {standard_task_runner.py:91} INFO - Job 6: Subtask load_to_gcs
[2024-06-26T13:04:44.047+0000] {task_command.py:426} INFO - Running <TaskInstance: etl_dag.load_to_gcs scheduled__2024-06-25T00:00:00+00:00 [running]> on host b3fb9a440c0a
[2024-06-26T13:04:44.138+0000] {taskinstance.py:2648} INFO - Exporting env vars: AIRFLOW_CTX_DAG_OWNER='***' AIRFLOW_CTX_DAG_ID='etl_dag' AIRFLOW_CTX_TASK_ID='load_to_gcs' AIRFLOW_CTX_EXECUTION_DATE='2024-06-25T00:00:00+00:00' AIRFLOW_CTX_TRY_NUMBER='2' AIRFLOW_CTX_DAG_RUN_ID='scheduled__2024-06-25T00:00:00+00:00'
[2024-06-26T13:04:44.139+0000] {taskinstance.py:430} INFO - ::endgroup::
[2024-06-26T13:04:44.140+0000] {sql_to_gcs.py:163} INFO - Executing query
[2024-06-26T13:04:44.148+0000] {taskinstance.py:441} INFO - ::group::Post task execution logs
[2024-06-26T13:04:44.159+0000] {taskinstance.py:2905} ERROR - Task failed with exception
Traceback (most recent call last):
  File "/home/airflow/.local/lib/python3.12/site-packages/airflow/models/taskinstance.py", line 465, in _execute_task
    result = _execute_callable(context=context, **execute_callable_kwargs)
             ^^^^^^^^^^^^^^^^^^^^^^^^^^^^^^^^^^^^^^^^^^^^^^^^^^^^^^^^^^^^^
  File "/home/airflow/.local/lib/python3.12/site-packages/airflow/models/taskinstance.py", line 432, in _execute_callable
    return execute_callable(context=context, **execute_callable_kwargs)
           ^^^^^^^^^^^^^^^^^^^^^^^^^^^^^^^^^^^^^^^^^^^^^^^^^^^^^^^^^^^^
  File "/home/airflow/.local/lib/python3.12/site-packages/airflow/models/baseoperator.py", line 401, in wrapper
    return func(self, *args, **kwargs)
           ^^^^^^^^^^^^^^^^^^^^^^^^^^^
  File "/home/airflow/.local/lib/python3.12/site-packages/airflow/providers/google/cloud/transfers/sql_to_gcs.py", line 164, in execute
    cursor = self.query()
             ^^^^^^^^^^^^
  File "/home/airflow/.local/lib/python3.12/site-packages/airflow/providers/google/cloud/transfers/postgres_to_gcs.py", line 138, in query
    conn = hook.get_conn()
           ^^^^^^^^^^^^^^^
  File "/home/airflow/.local/lib/python3.12/site-packages/airflow/providers/postgres/hooks/postgres.py", line 145, in get_conn
    conn = deepcopy(self.connection or self.get_connection(conn_id))
                                       ^^^^^^^^^^^^^^^^^^^^^^^^^^^^
  File "/home/airflow/.local/lib/python3.12/site-packages/airflow/hooks/base.py", line 83, in get_connection
    conn = Connection.get_connection_from_secrets(conn_id)
           ^^^^^^^^^^^^^^^^^^^^^^^^^^^^^^^^^^^^^^^^^^^^^^^
  File "/home/airflow/.local/lib/python3.12/site-packages/airflow/models/connection.py", line 519, in get_connection_from_secrets
    raise AirflowNotFoundException(f"The conn_id `{conn_id}` isn't defined")
airflow.exceptions.AirflowNotFoundException: The conn_id `DataOps` isn't defined
[2024-06-26T13:04:44.164+0000] {taskinstance.py:1206} INFO - Marking task as FAILED. dag_id=etl_dag, task_id=load_to_gcs, run_id=scheduled__2024-06-25T00:00:00+00:00, execution_date=20240625T000000, start_date=20240626T130443, end_date=20240626T130444
[2024-06-26T13:04:44.177+0000] {standard_task_runner.py:110} ERROR - Failed to execute job 6 for task load_to_gcs (The conn_id `DataOps` isn't defined; 155)
[2024-06-26T13:04:44.212+0000] {local_task_job_runner.py:240} INFO - Task exited with return code 1
[2024-06-26T13:04:44.240+0000] {taskinstance.py:3503} INFO - 0 downstream tasks scheduled from follow-on schedule check
[2024-06-26T13:04:44.244+0000] {local_task_job_runner.py:222} INFO - ::endgroup::
